Workbook

Sheet 발전소_2026
A1: ⚡ 발전소별 월간운영 실적 (2026)
A2: 🔥 Power Plant Monthly Operations Dashboard — Generation · Capacity Factor · Emissions
A4: 월 | B4: 발전소명 | C4: 사업유형 | D4: 설비용량(MW) | E4: 발전량(MWh) | F4: 가동률(%) | G4: 연료소비(TJ) | H4: 온실가스(tCO₂) | I4: 단위연료(MJ/kWh) | J4: 효율등급 | K4: 주요이슈 | L4: 운영상태
A5: 2026-01 | B5: 인천LNG 1호기 | C5: LNG | D5: 500 | E5: 315000 | F5: 86.5 | G5: 2356 | H5: 120330 | I5: =IFERROR(G5*1000/E5*1000,0) -> 7479.3651 | J5: =IF(F5>=95,"S",IF(F5>=85,"A",IF(F5>=70,"B",IF(F5>=50,"C","D")))) -> A | K5: 동절기 가동 | L5: 초과가동
A6: 2026-01 | B6: 인천LNG 2호기 | C6: LNG | D6: 500 | E6: 329000 | F6: 90.3 | G6: 2461 | H6: 125678 | I6: =IFERROR(G6*1000/E6*1000,0) -> 7480.2432 | J6: =IF(F6>=95,"S",IF(F6>=85,"A",IF(F6>=70,"B",IF(F6>=50,"C","D")))) -> A | K6: 정상가동 | L6: 정상
A7: 2026-01 | B7: 인천LNG 3호기 | C7: LNG | D7: 512 | E7: 344000 | F7: 92.1 | G7: 2573 | H7: 131408 | I7: =IFERROR(G7*1000/E7*1000,0) -> 7479.6512 | J7: =IF(F7>=95,"S",IF(F7>=85,"A",IF(F7>=70,"B",IF(F7>=50,"C","D")))) -> A | K7: 여름 진입 | L7: 초과가동
A8: 2026-01 | B8: 인천LNG 4호기 | C8: LNG | D8: 500 | E8: 323000 | F8: 88.7 | G8: 2416 | H8: 123386 | I8: =IFERROR(G8*1000/E8*1000,0) -> 7479.8762 | J8: =IF(F8>=95,"S",IF(F8>=85,"A",IF(F8>=70,"B",IF(F8>=50,"C","D")))) -> A | K8: 여름 진입 | L8: 초과가동
A9: 2026-01 | B9: 인천LNG 5호기 | C9: LNG | D9: 500 | E9: 334000 | F9: 91.7 | G9: 2498 | H9: 127588 | I9: =IFERROR(G9*1000/E9*1000,0) -> 7479.0419 | J9: =IF(F9>=95,"S",IF(F9>=85,"A",IF(F9>=70,"B",IF(F9>=50,"C","D")))) -> A | K9: 수요 정점 | L9: 안정
A10: 2026-01 | B10: 광양LNG 1호기 | C10: LNG | D10: 480 | E10: 311000 | F10: 88.8 | G10: 2326 | H10: 118802 | I10: =IFERROR(G10*1000/E10*1000,0) -> 7479.0997 | J10: =IF(F10>=95,"S",IF(F10>=85,"A",IF(F10>=70,"B",IF(F10>=50,"C","D")))) -> A | L10: 안정
A11: 2026-01 | B11: 광양LNG 2호기 | C11: LNG | D11: 480 | E11: 302000 | F11: 86.3 | G11: 2259 | H11: 115364 | I11: =IFERROR(G11*1000/E11*1000,0) -> 7480.1325 | J11: =IF(F11>=95,"S",IF(F11>=85,"A",IF(F11>=70,"B",IF(F11>=50,"C","D")))) -> A | K11: 혹서기 정점 | L11: 정상
A12: 2026-01 | B12: 광양LNG 3호기 | C12: LNG | D12: 495 | E12: 321000 | F12: 88.9 | G12: 2401 | H12: 122622 | I12: =IFERROR(G12*1000/E12*1000,0) -> 7479.7508 | J12: =IF(F12>=95,"S",IF(F12>=85,"A",IF(F12>=70,"B",IF(F12>=50,"C","D")))) -> A | K12: 기저부하 운영 | L12: 최적운영
A13: 2026-01 | B13: 광양LNG 4호기 | C13: LNG | D13: 500 | E13: 330000 | F13: 90.5 | G13: 2468 | H13: 126060 | I13: =IFERROR(G13*1000/E13*1000,0) -> 7478.7879 | J13: =IF(F13>=95,"S",IF(F13>=85,"A",IF(F13>=70,"B",IF(F13>=50,"C","D")))) -> A | K13: 정기점검 완료 | L13: 정기점검
A14: 2026-01 | B14: 평택LNG 1호기 | C14: LNG | D14: 520 | E14: 332000 | F14: 87.5 | G14: 2483 | H14: 126824 | I14: =IFERROR(G14*1000/E14*1000,0) -> 7478.9157 | J14: =IF(F14>=95,"S",IF(F14>=85,"A",IF(F14>=70,"B",IF(F14>=50,"C","D")))) -> A | K14: 혹한기 정점 | L14: 정기점검
A15: 2026-01 | B15: 평택LNG 2호기 | C15: LNG | D15: 520 | E15: 352000 | F15: 92.8 | G15: 2633 | H15: 134464 | I15: =IFERROR(G15*1000/E15*1000,0) -> 7480.1136 | J15: =IF(F15>=95,"S",IF(F15>=85,"A",IF(F15>=70,"B",IF(F15>=50,"C","D")))) -> A | K15: 동절기 가동 | L15: 정상
A16: 2026-01 | B16: 평택LNG 3호기 | C16: LNG | D16: 530 | E16: 351000 | F16: 90.8 | G16: 2625 | H16: 134082 | I16: =IFERROR(G16*1000/E16*1000,0) -> 7478.6325 | J16: =IF(F16>=95,"S",IF(F16>=85,"A",IF(F16>=70,"B",IF(F16>=50,"C","D")))) -> A | K16: 정상가동 | L16: 초과가동
A17: 2026-01 | B17: 보령LNG 1호기 | C17: LNG | D17: 510 | E17: 333000 | F17: 89.5 | G17: 2491 | H17: 127206 | I17: =IFERROR(G17*1000/E17*1000,0) -> 7480.4805 | J17: =IF(F17>=95,"S",IF(F17>=85,"A",IF(F17>=70,"B",IF(F17>=50,"C","D")))) -> A | K17: 혹서기 정점 | L17: 최적운영
A18: 2026-01 | B18: 보령LNG 2호기 | C18: LNG | D18: 510 | E18: 322000 | F18: 86.7 | G18: 2409 | H18: 123004 | I18: =IFERROR(G18*1000/E18*1000,0) -> 7481.3665 | J18: =IF(F18>=95,"S",IF(F18>=85,"A",IF(F18>=70,"B",IF(F18>=50,"C","D")))) -> A | K18: 기저부하 운영 | L18: 안정
A19: 2026-01 | B19: 동해LNG 1호기 | C19: LNG | D19: 495 | E19: 317000 | F19: 87.9 | G19: 2371 | H19: 121094 | I19: =IFERROR(G19*1000/E19*1000,0) -> 7479.4953 | J19: =IF(F19>=95,"S",IF(F19>=85,"A",IF(F19>=70,"B",IF(F19>=50,"C","D")))) -> A | K19: 안정 가동 | L19: 정상
A20: 2026-01 | B20: PT.KPE | C20: 부생가스 | D20: 200 | E20: 125000 | F20: 86.2 | G20: 928 | H20: 37625 | I20: =IFERROR(G20*1000/E20*1000,0) -> 7424 | J20: =IF(F20>=95,"S",IF(F20>=85,"A",IF(F20>=70,"B",IF(F20>=50,"C","D")))) -> A | K20: 정상 가동 | L20: 정상
A21: 2026-01 | B21: PT.KPE 2호기 | C21: 부생가스 | D21: 220 | E21: 138000 | F21: 86.4 | G21: 1024 | H21: 41538 | I21: =IFERROR(G21*1000/E21*1000,0) -> 7420.2899 | J21: =IF(F21>=95,"S",IF(F21>=85,"A",IF(F21>=70,"B",IF(F21>=50,"C","D")))) -> A | K21: 효율 개선 | L21: 초과가동
A22: 2026-01 | B22: 신안 해상풍력 1단계 | C22: 재생 | D22: 147 | E22: 41000 | F22: 38.5 | G22: 0 | H22: 0 | I22: 0 | J22: =IF(F22>=95,"S",IF(F22>=85,"A",IF(F22>=70,"B",IF(F22>=50,"C","D")))) -> D | K22: 여름 풍속 약화 | L22: 정기점검
A23: 2026-01 | B23: 신안 해상풍력 2단계 | C23: 재생 | D23: 320 | E23: 90000 | F23: 38.6 | G23: 0 | H23: 0 | I23: 0 | J23: =IF(F23>=95,"S",IF(F23>=85,"A",IF(F23>=70,"B",IF(F23>=50,"C","D")))) -> D | K23: ESS 연계 | L23: 최적운영
A24: 2026-01 | B24: 영덕 해상풍력 | C24: 재생 | D24: 250 | E24: 68000 | F24: 37.3 | G24: 0 | H24: 0 | I24: 0 | J24: =IF(F24>=95,"S",IF(F24>=85,"A",IF(F24>=70,"B",IF(F24>=50,"C","D")))) -> D | K24: REC 인증 갱신 | L24: 정상
A25: 2026-01 | B25: 제주 해상풍력 | C25: 재생 | D25: 180 | E25: 55000 | F25: 42.5 | G25: 0 | H25: 0 | I25: 0 | J25: =IF(F25>=95,"S",IF(F25>=85,"A",IF(F25>=70,"B",IF(F25>=50,"C","D")))) -> D | K25: ESS 연계 | L25: 최적운영
A26: 2026-01 | B26: 강원 육상풍력 | C26: 재생 | D26: 95 | E26: 26000 | F26: 38.6 | G26: 0 | H26: 0 | I26: 0 | J26: =IF(F26>=95,"S",IF(F26>=85,"A",IF(F26>=70,"B",IF(F26>=50,"C","D")))) -> D | L26: 안정
A27: 2026-01 | B27: 울주 태양광 | C27: 재생 | D27: 32 | E27: 1000 | F27: 6.6 | G27: 0 | H27: 0 | I27: 0 | J27: =IF(F27>=95,"S",IF(F27>=85,"A",IF(F27>=70,"B",IF(F27>=50,"C","D")))) -> D | K27: 겨울 풍속 양호 | L27: 정상
A28: 2026-01 | B28: 새만금 태양광 | C28: 재생 | D28: 220 | E28: 13000 | F28: 8.2 | G28: 0 | H28: 0 | I28: 0 | J28: =IF(F28>=95,"S",IF(F28>=85,"A",IF(F28>=70,"B",IF(F28>=50,"C","D")))) -> D | K28: REC 인증 갱신 | L28: 정상
A29: 2026-01 | B29: 영광 태양광 | C29: 재생 | D29: 85 | E29: 4000 | F29: 7.7 | G29: 0 | H29: 0 | I29: 0 | J29: =IF(F29>=95,"S",IF(F29>=85,"A",IF(F29>=70,"B",IF(F29>=50,"C","D")))) -> D | K29: 가을 풍속 회복 | L29: 최적운영
A30: 2026-01 | B30: 군산 태양광 | C30: 재생 | D30: 60 | E30: 2000 | F30: 6.4 | G30: 0 | H30: 0 | I30: 0 | J30: =IF(F30>=95,"S",IF(F30>=85,"A",IF(F30>=70,"B",IF(F30>=50,"C","D")))) -> D | K30: 일조량 정점 | L30: 정상
A31: 2026-01 | B31: 해남 태양광 | C31: 재생 | D31: 75 | E31: 4000 | F31: 7.5 | G31: 0 | H31: 0 | I31: 0 | J31: =IF(F31>=95,"S",IF(F31>=85,"A",IF(F31>=70,"B",IF(F31>=50,"C","D")))) -> D | K31: 신규 가동 | L31: 최적운영
A32: 2026-01 | B32: 서산 수소혼소 1호기 | C32: 수소혼소 | D32: 460 | E32: 276000 | F32: 82.5 | G32: 1891 | H32: 73140 | I32: =IFERROR(G32*1000/E32*1000,0) -> 6851.4493 | J32: =IF(F32>=95,"S",IF(F32>=85,"A",IF(F32>=70,"B",IF(F32>=50,"C","D")))) -> B | K32: 혼소율 상향 | L32: 정상
A33: 2026-01 | B33: 서산 수소혼소 2호기 | C33: 수소혼소 | D33: 460 | E33: 273000 | F33: 81.5 | G33: 1870 | H33: 72345 | I33: =IFERROR(G33*1000/E33*1000,0) -> 6849.8168 | J33: =IF(F33>=95,"S",IF(F33>=85,"A",IF(F33>=70,"B",IF(F33>=50,"C","D")))) -> B | K33: 탄소저감 18% | L33: 초과가동
A34: 2026-01 | B34: 인천 ESS 1호기 | C34: ESS | D34: 80 | E34: 25000 | F34: 44.1 | G34: 0 | H34: 0 | I34: 0 | J34: =IF(F34>=95,"S",IF(F34>=85,"A",IF(F34>=70,"B",IF(F34>=50,"C","D")))) -> D | K34: 안전점검 완료 | L34: 최적운영
A35: 2026-01 | B35: 인천 ESS 2호기 | C35: ESS | D35: 80 | E35: 25000 | F35: 44.2 | G35: 0 | H35: 0 | I35: 0 | J35: =IF(F35>=95,"S",IF(F35>=85,"A",IF(F35>=70,"B",IF(F35>=50,"C","D")))) -> D | K35: 충방전 99.2% | L35: 정기점검
A36: 2026-01 | B36: 평택 ESS | C36: ESS | D36: 100 | E36: 27000 | F36: 37.8 | G36: 0 | H36: 0 | I36: 0 | J36: =IF(F36>=95,"S",IF(F36>=85,"A",IF(F36>=70,"B",IF(F36>=50,"C","D")))) -> D | K36: REC 발급 완료 | L36: 정상
A37: 2026-02 | B37: 인천LNG 1호기 | C37: LNG | D37: 500 | E37: 304000 | F37: 83.5 | G37: 2274 | H37: 116128 | I37: =IFERROR(G37*1000/E37*1000,0) -> 7480.2632 | J37: =IF(F37>=95,"S",IF(F37>=85,"A",IF(F37>=70,"B",IF(F37>=50,"C","D")))) -> B | K37: 기저부하 운영 | L37: 안정
A38: 2026-02 | B38: 인천LNG 2호기 | C38: LNG | D38: 500 | E38: 328000 | F38: 89.9 | G38: 2453 | H38: 125296 | I38: =IFERROR(G38*1000/E38*1000,0) -> 7478.6585 | J38: =IF(F38>=95,"S",IF(F38>=85,"A",IF(F38>=70,"B",IF(F38>=50,"C","D")))) -> A | K38: 동절기 가동 | L38: 최적운영
A39: 2026-02 | B39: 인천LNG 3호기 | C39: LNG | D39: 512 | E39: 320000 | F39: 85.7 | G39: 2394 | H39: 122240 | I39: =IFERROR(G39*1000/E39*1000,0) -> 7481.25 | J39: =IF(F39>=95,"S",IF(F39>=85,"A",IF(F39>=70,"B",IF(F39>=50,"C","D")))) -> A | K39: 정기점검 완료 | L39: 정상
A40: 2026-02 | B40: 인천LNG 4호기 | C40: LNG | D40: 500 | E40: 321000 | F40: 88 | G40: 2401 | H40: 122622 | I40: =IFERROR(G40*1000/E40*1000,0) -> 7479.7508 | J40: =IF(F40>=95,"S",IF(F40>=85,"A",IF(F40>=70,"B",IF(F40>=50,"C","D")))) -> A | K40: 수요 정점 | L40: 초과가동
A41: 2026-02 | B41: 인천LNG 5호기 | C41: LNG | D41: 500 | E41: 323000 | F41: 88.5 | G41: 2416 | H41: 123386 | I41: =IFERROR(G41*1000/E41*1000,0) -> 7479.8762 | J41: =IF(F41>=95,"S",IF(F41>=85,"A",IF(F41>=70,"B",IF(F41>=50,"C","D")))) -> A | K41: 수요 정점 | L41: 정기점검
...

Sheet 📈 사업유형_요약
A1: ⚡ 사업유형별 연간 요약 (2026)
A3: 사업유형 | B3: 발전소 수 | C3: 총 설비용량(MW) | D3: 연간 발전량(MWh) | E3: 연간 온실가스(tCO₂) | F3: 평균 가동률(%)
A4: LNG | B4: 15 | C4: 7552 | D4: =SUMIF(발전소_2026!C5:C388,"LNG",발전소_2026!E5:E388) -> 55353000 | E4: =SUMIF(발전소_2026!C5:C388,"LNG",발전소_2026!H5:H388) -> 21144846 | F4: =AVERAGEIF(발전소_2026!C5:C388,"LNG",발전소_2026!F5:F388) -> 83.805556
A5: 부생가스 | B5: 2 | C5: 420 | D5: =SUMIF(발전소_2026!C5:C388,"부생가스",발전소_2026!E5:E388) -> 3201000 | E5: =SUMIF(발전소_2026!C5:C388,"부생가스",발전소_2026!H5:H388) -> 963501 | F5: =AVERAGEIF(발전소_2026!C5:C388,"부생가스",발전소_2026!F5:F388) -> 87.3875
A6: 재생 | B6: 10 | C6: 1464 | D6: =SUMIF(발전소_2026!C5:C388,"재생",발전소_2026!E5:E388) -> 3694000 | E6: =SUMIF(발전소_2026!C5:C388,"재생",발전소_2026!H5:H388) -> 0 | F6: =AVERAGEIF(발전소_2026!C5:C388,"재생",발전소_2026!F5:F388) -> 25.004167
A7: 수소혼소 | B7: 2 | C7: 920 | D7: =SUMIF(발전소_2026!C5:C388,"수소혼소",발전소_2026!E5:E388) -> 6159000 | E7: =SUMIF(발전소_2026!C5:C388,"수소혼소",발전소_2026!H5:H388) -> 1632135 | F7: =AVERAGEIF(발전소_2026!C5:C388,"수소혼소",발전소_2026!F5:F388) -> 76.5875
A8: ESS | B8: 3 | C8: 260 | D8: =SUMIF(발전소_2026!C5:C388,"ESS",발전소_2026!E5:E388) -> 918000 | E8: =SUMIF(발전소_2026!C5:C388,"ESS",발전소_2026!H5:H388) -> 0 | F8: =AVERAGEIF(발전소_2026!C5:C388,"ESS",발전소_2026!F5:F388) -> 41.247222
A9: 전체 합계 | B9: =SUM(B4:B8) -> 32 | C9: =SUM(C4:C8) -> 10616 | D9: =SUM(D4:D8) -> 69325000 | E9: =SUM(E4:E8) -> 23740482 | F9: =AVERAGE(F4:F8) -> 62.806389
