Workbook

Sheet 거래내역_2026
A1: 💎 GLOBAL TRADING LEDGER 2026
A2: ★ Premium Trade Transaction Records — Steel · Energy · Mobility · Food · Bio ★
A4: 거래일 | B4: 거래번호 | C4: 사업부문 | D4: 제품군 | E4: 원산지 | F4: 도착지 | G4: 고객사 | H4: 거래량(톤) | I4: 단가(USD) | J4: 총액(USD) | K4: 거래유형 | L4: 담당지점 | M4: 결제조건 | N4: 영업이익률(%) | O4: 비고
A5: 2026-01-03 | B5: TR-2026-0001 | C5: 바이오 | D5: CPO 정제 | E5: 한국 | F5: 미국 | G5: Vinamilk | H5: 8927 | I5: 1102 | J5: =H5*I5 -> 9837554 | K5: 그룹사 | L5: 휴스턴 | M5: T/T 30일 | N5: 3.5 | O5: ESG 등급 A
A6: 2026-01-04 | B6: TR-2026-0002 | C6: 철강 | D6: 냉연 | E6: 중국 | F6: 베트남 | G6: Hoa Phat Group | H6: 5933 | I6: 899 | J6: =H6*I6 -> 5333767 | K6: 제3자 | L6: 이스탄불 | M6: LC 90일 | N6: 5 | O6: 프리미엄 등급
A7: 2026-01-06 | B7: TR-2026-0003 | C7: 철강 | D7: 열연 | E7: 인도 | F7: 독일 | G7: Saudi Steel | H7: 4100 | I7: 546 | J7: =H7*I7 -> 2238600 | K7: 그룹사 | L7: 방콕 | M7: T/T 즉시 | N7: 8.1 | O7: 재계약 갱신
A8: 2026-01-07 | B8: TR-2026-0004 | C8: 모빌리티 | D8: 니켈 | E8: 한국 | F8: 체코 | G8: Skoda Auto | H8: 418 | I8: 18930 | J8: =H8*I8 -> 7912740 | K8: 그룹사 | L8: 선전 | M8: T/T 45일 | N8: 9.9 | O8: 고부가 제품
A9: 2026-01-08 | B9: TR-2026-0005 | C9: 철강 | D9: 자동차강판 | E9: 일본 | F9: 태국 | G9: JSW Steel | H9: 6256 | I9: 1091 | J9: =H9*I9 -> 6825296 | K9: 그룹사 | L9: 몬테레이 | M9: LC 30일 | N9: 4.4 | O9: 고부가 제품
A10: 2026-01-10 | B10: TR-2026-0006 | C10: 철강 | D10: 전기강판 | E10: 한국 | F10: 사우디 | G10: Tesla Inc | H10: 3949 | I10: 2175 | J10: =H10*I10 -> 8589075 | K10: 제3자 | L10: 자카르타 | M10: LC 30일 | N10: 7.5 | O10: 프리미엄 등급
A11: 2026-01-11 | B11: TR-2026-0007 | C11: 모빌리티 | D11: 동박 | E11: 필리핀 | F11: 한국 | G11: LG Energy Solution | H11: 569 | I11: 18431 | J11: =H11*I11 -> 10487239 | K11: 그룹사 | L11: 프랑크푸르트 | M11: LC 90일 | N11: 13.4 | O11: 프리미엄 등급
A12: 2026-01-14 | B12: TR-2026-0008 | C12: 철강 | D12: 후판 | E12: 한국 | F12: 미국 | G12: POSCO Vietnam | H12: 4232 | I12: 742 | J12: =H12*I12 -> 3140144 | K12: 그룹사 | L12: 싱가포르 | M12: T/T 즉시 | N12: 5.2 | O12: 스팟 거래
A13: 2026-01-15 | B13: TR-2026-0009 | C13: 에너지 | D13: 석유제품 | E13: 카타르 | F13: 중국 | G13: JFE Steel | H13: 59875 | I13: 83.4 | J13: =H13*I13 -> 4993575 | K13: 그룹사 | L13: 도쿄 | M13: CIF | N13: 2.8 | O13: 그린 인증 제품
A14: 2026-01-17 | B14: TR-2026-0010 | C14: 에너지 | D14: 석유제품 | E14: 사우디 | F14: 일본 | G14: Sinopec | H14: 33885 | I14: 82.4 | J14: =H14*I14 -> 2792124 | K14: 제3자 | L14: 선릉 본사 | M14: LC 30일 | N14: 1.7 | O14: 장기 파트너
A15: 2026-01-18 | B15: TR-2026-0011 | C15: 에너지 | D15: 석유제품 | E15: 호주 | F15: 중국 | G15: GS Caltex | H15: 45436 | I15: 80.2 | J15: =H15*I15 -> 3643967.2 | K15: 그룹사 | L15: 도쿄 | M15: CIF | N15: 2.3 | O15: 장기계약 분
A16: 2026-01-24 | B16: TR-2026-0012 | C16: 철강 | D16: 후판 | E16: 일본 | F16: 터키 | G16: SUS Steel | H16: 2462 | I16: 734 | J16: =H16*I16 -> 1807108 | K16: 제3자 | L16: 이스탄불 | M16: T/T 45일 | N16: 8.5 | O16: 친환경 시리즈
... A21: 2026-02-02 | B21: TR-2026-0017 | C21: 식량 | D21: 팜오일 | E21: 아르헨티나 | F21: 한국 | G21: 농협사료 | H21: 17410 | I21: 977 | J21: =H21*I21 -> 17009570 | K21: 그룹사 | L21: 발렌시아 | M21: T/T 60일 | N21: 3.5 | O21: 고부가 제품
A22: 2026-02-05 | B22: TR-2026-0018 | C22: 에너지 | D22: LNG | E22: 싱가포르 | F22: 대만 | G22: Sinopec | H22: 41907 | I22: 12 | J22: =H22*I22 -> 502884 | K22: 그룹사 | L22: 도쿄 | M22: LC 90일 | N22: 1.9
A23: 2026-02-10 | B23: TR-2026-0019 | C23: 식량 | D23: 밀 | E23: 아르헨티나 | F23: 스페인 | G23: GASC | H23: 17485 | I23: 276 | J23: =H23*I23 -> 4825860 | K23: 그룹사 | L23: 텐진 | M23: CIF | N23: 3.6 | O23: 장기 파트너
A24: 2026-02-11 | B24: TR-2026-0020 | C24: 식량 | D24: 콩 | E24: 브라질 | F24: 중국 | G24: COFCO | H24: 18424 | I24: 449 | J24: =H24*I24 -> 8272376 | K24: 제3자 | L24: 튀니스 | M24: T/T 즉시 | N24: 4.5 | O24: ESG 등급 A
A25: 2026-02-17 | B25: TR-2026-0021 | C25: 에너지 | D25: LPG | E25: 인니 | F25: 중국 | G25: JFE Steel | H25: 46211 | I25: 622 | J25: =H25*I25 -> 28743242 | K25: 제3자 | L25: 선릉 본사 | M25: LC 90일 | N25: 2.2 | O25: 고부가 제품
A26: 2026-02-18 | B26: TR-2026-0022 | C26: 철강 | D26: 선재 | E26: 일본 | F26: 일본 | G26: SUS Steel | H26: 2899 | I26: 691 | J26: =H26*I26 -> 2003209 | K26: 제3자 | L26: 리야드 | M26: LC 60일 | N26: 4
A27: 2026-02-19 | B27: TR-2026-0023 | C27: 철강 | D27: STS | E27: 일본 | F27: 베트남 | G27: Tesla Inc | H27: 5705 | I27: 1899 | J27: =H27*I27 -> 10833795 | K27: 그룹사 | L27: 방콕 | M27: T/T 45일 | N27: 8.9 | O27: 고부가 제품
A28: 2026-02-20 | B28: TR-2026-0024 | C28: 철강 | D28: 도금강판 | E28: 인도 | F28: 말레이시아 | G28: Ternium | H28: 5500 | I28: 985 | J28: =H28*I28 -> 5417500 | K28: 그룹사 | L28: 이스탄불 | M28: LC 90일 | N28: 8.1
A29: 2026-02-21 | B29: TR-2026-0025 | C29: 철강 | D29: 자동차강판 | E29: 인도 | F29: 터키 | G29: JSW Steel | H29: 3128 | I29: 1098 | J29: =H29*I29 -> 3434544 | K29: 그룹사 | L29: 몬테레이 | M29: T/T 30일 | N29: 6.3 | O29: 신규 고객
A30: 2026-02-24 | B30: TR-2026-0026 | C30: 철강 | D30: 열연 | E30: 일본 | F30: 인도네시아 | G30: POSCO Vietnam | H30: 5669 | I30: 559 | J30: =H30*I30 -> 3168971 | K30: 그룹사 | L30: 두바이 | M30: LC 60일 | N30: 7.7 | O30: 장기 파트너
A31: 2026-02-25 | B31: TR-2026-0027 | C31: 철강 | D31: 도금강판 | E31: 일본 | F31: 독일 | G31: Saudi Steel | H31: 4449 | I31: 957 | J31: =H31*I31 -> 4257693 | K31: 그룹사 | L31: 프랑크푸르트 | M31: LC 90일 | N31: 8.9 | O31: ESG 등급 A
A32: 2026-02-26 | B32: TR-2026-0028 | C32: 철강 | D32: STS | E32: 일본 | F32: 사우디 | G32: PT.KRAKATAU STEEL | H32: 3259 | I32: 1822 | J32: =H32*I32 -> 5937898 | K32: 제3자 | L32: 쿠알라룸푸르 | M32: T/T 즉시 | N32: 4.8 | O32: ESG 등급 A
A33: 2026-03-02 | B33: TR-2026-0029 | C33: 철강 | D33: STS | E33: 일본 | F33: 미국 | G33: Tofas | H33: 4168 | I33: 1849 | J33: =H33*I33 -> 7706632 | K33: 제3자 | L33: 리야드 | M33: LC 90일 | N33: 7.1 | O33: 탄소저감 인증
A34: 2026-03-03 | B34: TR-2026-0030 | C34: 식량 | D34: 귀리 | E34: 미국 | F34: 이집트 | G34: GASC | H34: 21063 | I34: 353 | J34: =H34*I34 -> 7435239 | K34: 제3자 | L34: 카이로 | M34: T/T 30일 | N34: 4.1 | O34: ESG 등급 A
A35: 2026-03-04 | B35: TR-2026-0031 | C35: 에너지 | D35: 석유제품 | E35: 사우디 | F35: 일본 | G35: GS EPS | H35: 59558 | I35: 85.6 | J35: =H35*I35 -> 5098164.8 | K35: 제3자 | L35: 상하이 | M35: LC 30일 | N35: 2 | O35: ESG 등급 A
A36: 2026-03-06 | B36: TR-2026-0032 | C36: 철강 | D36: 냉연 | E36: 중국 | F36: 싱가포르 | G36: Saudi Steel | H36: 5511 | I36: 916 | J36: =H36*I36 -> 5048076 | K36: 그룹사 | L36: 쿠알라룸푸르 | M36: LC 60일 | N36: 8.8 | O36: 재계약 갱신
A37: 2026-03-07 | B37: TR-2026-0033 | C37: 바이오 | D37: CPO 정제 | E37: 인니 | F37: 유럽 | G37: Vinamilk | H37: 3829 | I37: 1127 | J37: =H37*I37 -> 4315283 | K37: 그룹사 | L37: 상하이 | M37: T/T 45일 | N37: 3.3 | O37: ESG 등급 A
A38: 2026-03-08 | B38: TR-2026-0034 | C38: 철강 | D38: 열연 | E38: 중국 | F38: 태국 | G38: Mitsubishi Steel | H38: 4963 | I38: 558 | J38: =H38*I38 -> 2769354 | K38: 그룹사 | L38: 자카르타 | M38: T/T 즉시 | N38: 4.6 | O38: 신규 고객
A39: 2026-03-09 | B39: TR-2026-0035 | C39: 에너지 | D39: LPG | E39: 미국 | F39: 중국 | G39: GS EPS | H39: 51629 | I39: 605 | J39: =H39*I39 -> 31235545 | K39: 그룹사 | L39: 타이베이 | M39: T/T 30일 | N39: 2.6 | O39: 친환경 시리즈
A40: 2026-03-12 | B40: TR-2026-0036 | C40: 철강 | D40: 자동차강판 | E40: 일본 | F40: 인도네시아 | G40: Mitsubishi Steel | H40: 3101 | I40: 1065 | J40: =H40*I40 -> 3302565 | K40: 그룹사 | L40: 두바이 | M40: LC 90일 | N40: 3.9 | O40: 장기계약 분
... A45: 2026-03-20 | B45: TR-2026-0041 | C45: 모빌리티 | D45: 니켈 | E45: 인니 | F45: 폴란드 | G45: SK On | H45: 643 | I45: 18934 | J45: =H45*I45 -> 12174562 | K45: 그룹사 | L45: 뮌헨 | M45: CIF | N45: 10.4 | O45: 탄소저감 인증
A46: 2026-03-21 | B46: TR-2026-0042 | C46: 철강 | D46: 자동차강판 | E46: 한국 | F46: 미국 | G46: Outokumpu | H46: 1717 | I46: 1064 | J46: =H46*I46 -> 1826888 | K46: 그룹사 | L46: 휴스턴 | M46: LC 30일 | N46: 4
A47: 2026-03-22 | B47: TR-2026-0043 | C47: 철강 | D47: 후판 | E47: 한국 | F47: UAE | G47: Outokumpu | H47: 2755 | I47: 732 | J47: =H47*I47 -> 2016660 | K47: 그룹사 | L47: 두바이 | M47: T/T 즉시 | N47: 6.1 | O47: 그린 인증 제품
A48: 2026-03-23 | B48: TR-2026-0044 | C48: 식량 | D48: 팜오일 | E48: 아르헨티나 | F48: 인도 | G48: ODC Tunisia | H48: 16011 | I48: 965 | J48: =H48*I48 -> 15450615 | K48: 제3자 | L48: 상하이 | M48: CIF | N48: 3.1 | O48: 탄소저감 인증
A49: 2026-03-24 | B49: TR-2026-0045 | C49: 철강 | D49: 전기강판 | E49: 일본 | F49: 태국 | G49: Hoa Phat Group | H49: 3290 | I49: 2177 | J49: =H49*I49 -> 7162330 | K49: 제3자 | L49: 몬테레이 | M49: T/T 30일 | N49: 3.7 | O49: 신규 고객
...

Sheet 📊 부문별_분석
A1: 💎 사업부문별 거래 분석 (2026)
A3: 사업부문 | B3: 거래 건수 | C3: 총 거래량(톤) | D3: 총 거래액(USD) | E3: 평균 단가(USD) | F3: 평균 이익률(%)
A4: 철강 | B4: =COUNTIF(거래내역_2026!C5:C204,"철강") -> 70 | C4: =SUMIF(거래내역_2026!C5:C204,"철강",거래내역_2026!H5:H204) -> 276666 | D4: =SUMIF(거래내역_2026!C5:C204,"철강",거래내역_2026!J5:J204) -> 297645737 | E4: =AVERAGEIF(거래내역_2026!C5:C204,"철강",거래내역_2026!I5:I204) -> 1066.7571 | F4: =AVERAGEIF(거래내역_2026!C5:C204,"철강",거래내역_2026!N5:N204) -> 6.2528571
A5: 에너지 | B5: =COUNTIF(거래내역_2026!C5:C204,"에너지") -> 50 | C5: =SUMIF(거래내역_2026!C5:C204,"에너지",거래내역_2026!H5:H204) -> 2185956 | D5: =SUMIF(거래내역_2026!C5:C204,"에너지",거래내역_2026!J5:J204) -> 2.3422454e+09 | E5: =AVERAGEIF(거래내역_2026!C5:C204,"에너지",거래내역_2026!I5:I204) -> 1112.562 | F5: =AVERAGEIF(거래내역_2026!C5:C204,"에너지",거래내역_2026!N5:N204) -> 2.136
A6: 모빌리티 | B6: =COUNTIF(거래내역_2026!C5:C204,"모빌리티") -> 45 | C6: =SUMIF(거래내역_2026!C5:C204,"모빌리티",거래내역_2026!H5:H204) -> 23796 | D6: =SUMIF(거래내역_2026!C5:C204,"모빌리티",거래내역_2026!J5:J204) -> 504036563 | E6: =AVERAGEIF(거래내역_2026!C5:C204,"모빌리티",거래내역_2026!I5:I204) -> 21355.133 | F6: =AVERAGEIF(거래내역_2026!C5:C204,"모빌리티",거래내역_2026!N5:N204) -> 10.913333
A7: 식량 | B7: =COUNTIF(거래내역_2026!C5:C204,"식량") -> 25 | C7: =SUMIF(거래내역_2026!C5:C204,"식량",거래내역_2026!H5:H204) -> 390645 | D7: =SUMIF(거래내역_2026!C5:C204,"식량",거래내역_2026!J5:J204) -> 169101976 | E7: =AVERAGEIF(거래내역_2026!C5:C204,"식량",거래내역_2026!I5:I204) -> 443.88 | F7: =AVERAGEIF(거래내역_2026!C5:C204,"식량",거래내역_2026!N5:N204) -> 3.908
A8: 바이오 | B8: =COUNTIF(거래내역_2026!C5:C204,"바이오") -> 10 | C8: =SUMIF(거래내역_2026!C5:C204,"바이오",거래내역_2026!H5:H204) -> 59234 | D8: =SUMIF(거래내역_2026!C5:C204,"바이오",거래내역_2026!J5:J204) -> 86581265 | E8: =AVERAGEIF(거래내역_2026!C5:C204,"바이오",거래내역_2026!I5:I204) -> 1449 | F8: =AVERAGEIF(거래내역_2026!C5:C204,"바이오",거래내역_2026!N5:N204) -> 4.36
A9: 💎 GRAND TOTAL | B9: =SUM(B4:B8) -> 200 | C9: =SUM(C4:C8) -> 2936297 | D9: =SUM(D4:D8) -> 3.399611e+09 | E9: =AVERAGE(E4:E8) -> 5085.4665 | F9: =AVERAGE(F4:F8) -> 5.5140381
